Workbook

Sheet Influencer Database
A1: Name | B1: Instagram ID | C1: Followers | D1: Primary Category | E1: Category also Fits in | F1: Brands Collaborated With
A2: Jannat Zubair Rahmani | B2: @jannatzubair29 | C2: 51600000 | D2: Fashion & Lifestyle | E2: Beauty; Women's Fashion; Fashion Entertainment | F2: Garnier; Disney+ Hotstar; Maruti Suzuki; Nayaab; JZee (own labels)
A3: Anushka Sen | B3: @anushkasen0408 | C3: 37800000 | D3: Fashion & Lifestyle | E3: Beauty; Travel | F3: Samsung Galaxy; Jeju Tourism
A4: Avneet Kaur | B4: @avneetkaur_13 | C4: 30600000 | D4: Fashion & Lifestyle | E4: Beauty; Travel; Fashion Entertainment | F4: Clovia
A5: Arishfa Khan | B5: @arishfakhan138 | C5: 29200000 | D5: Beauty & Fashion | E5: Fashion Entertainment; Lifestyle | F5: Not verified
A6: Rohit Zinjurke | B6: @rohittt_09_ | C6: 27891269 | D6: Fashion Entertainment | E6: Men's Fashion; Lifestyle | F6: Not verified
A7: Elvish Yadav | B7: @elvish_yadav | C7: 21100000 | D7: Lifestyle | E7: Men's Fashion; Fashion Entertainment | F7: Systumm Clothing (own label); Elo Elo
A8: Ashish Chanchlani | B8: @ashishchanchlani | C8: 17700000 | D8: Fashion Entertainment | E8: Comedy; Lifestyle | F8: The Souled Store
A9: Garima Chaurasia (Gima Ashi) | B9: @gima_ashi | C9: 14600000 | D9: Fashion & Lifestyle | E9: Women's Fashion; Travel; Fashion Entertainment | F9: Not verified
A10: Lilly Singh | B10: @lilly | C10: 13200000 | D10: Fashion Entertainment | E10: Comedy; Lifestyle | F10: Ardene
A11: Abhishek Malhan (Fukra Insaan) | B11: @fukra_insaan | C11: 12500000 | D11: Lifestyle Vlogging | E11: Lifestyle; Fashion Entertainment | F11: Not verified
A12: Adnaan Shaikh | B12: @adnaan_07dz | C12: 11600000 | D12: Fashion Entertainment | E12: Men's Fashion; Lifestyle | F12: Not verified
A13: Sourav Joshi | B13: @souravjoshivlogs | C13: 10900000 | D13: Lifestyle Vlogging | E13: Lifestyle; Travel | F13: Lava
... A80: Aashna Hegde | B80: @aashnahegde | C80: 1000000 | D80: Beauty & Fashion | E80: Lifestyle; Lifestyle Vlogging | F80: L'Oréal Professionnel; Tata CLiQ Palette; Fashion Nova

Sheet Sources & Verification
A1: Creator Name | B1: Instagram URL | C1: Followers Used | D1: Follower Basis | E1: Follower Source | F1: Follower Source URL | G1: Source Snapshot | H1: Collaboration Brand(s) | I1: Evidence URL | J1: Evidence Type | K1: Evidence Strength | L1: Verification Date | M1: Notes
A2: Jannat Zubair Rahmani | B2: https://www.instagram.com/jannatzubair29/ | C2: 51600000 | D2: Estimate (~50-52M) | E2: Qoruz (Aug 2026) | F2: https://qoruz.com/jannatzubair29/instagram | G2: 2026-08 | H2: Garnier; Disney+ Hotstar; Maruti Suzuki | I2: https://www.flickonclick.com/jannat-zubair-biography/ | J2: Entertainment media profile | K2: Reported | L2: 2026-10-11 | M2: Former TV actor; now primarily an Instagram creator. Review against your celebrity-exclusion policy.
A3: Jannat Zubair Rahmani | B3: https://www.instagram.com/jannatzubair29/ | C3: 51600000 | D3: Estimate (~50-52M) | E3: Qoruz (Aug 2026) | F3: https://qoruz.com/jannatzubair29/instagram | G3: 2026-08 | H3: Nayaab; JZee (own labels) | I3: https://filmibeat.com/television/news/2025/jannat-zubair-from-actress-to-entrepreneur-redefining-success-at-a-young-age-443197.html | J3: Entertainment media report (2025) | K3: Reported | L3: 2026-10-11
A4: Anushka Sen | B4: https://www.instagram.com/anushkasen0408/ | C4: 37800000 | D4: Estimate (37.7-37.9M) | E4: Qoruz | F4: https://qoruz.com/anushkasen_04/instagram | G4: 2026 | H4: Samsung Galaxy; Jeju Tourism | I4: https://creatordb.app/creatorstats/anushkasen0408/ | J4: Analytics platform brand-partnership log | K4: Reported | L4: 2026-10-11 | M4: Former child/TV actor; review against your celebrity-exclusion policy.
A5: Avneet Kaur | B5: https://www.instagram.com/avneetkaur_13/ | C5: 30600000 | D5: Estimate (30.6-32.3M) | E5: Qoruz | F5: https://qoruz.com/avneetkaur_13/instagram | G5: 2026 | H5: Clovia | I5: https://www.mediainfoline.com/advertising/avneet-kaur-clovia-bralettes | J5: Campaign report | K5: Confirmed | L5: 2026-10-11 | M5: Former child/TV actor with film roles; review against your celebrity-exclusion policy.
A6: Arishfa Khan | B6: https://www.instagram.com/arishfakhan138/ | C6: 29200000 | D6: Estimate (~29.2M) | E6: HypeAuditor / Qoruz | F6: https://hypeauditor.com/instagram/arishfakhan138/ | G6: 2026 | H6: No specific brand collaboration verified | I6: https://qoruz.com/arishfakhan138/instagram | J6: Directory profile | K6: Unverified | L6: 2026-10-11
A7: Rohit Zinjurke | B7: https://www.instagram.com/rohittt_09_/ | C7: 27891269 | D7: Exact (tracker) | E7: DolphinRadar | F7: https://www.dolphinradar.com/starInfo/rohittt_09_ | G7: 2026 | H7: Luxury brand collaborations described; no brand named | I7: https://www.dolphinradar.com/starInfo/rohittt_09_ | J7: Analytics profile | K7: Unverified | L7: 2026-10-11
A8: Elvish Yadav | B8: https://www.instagram.com/elvish_yadav/ | C8: 21100000 | D8: Estimate (~21.1M) | E8: Qoruz (Aug 2026) | F8: https://qoruz.com/theindianviner/instagram | G8: 2026-08 | H8: Systumm Clothing (own label) | I8: https://blog.jumpp.finance/financial-management/net-worth/elvish-yadav-net-wort/ | J8: Finance blog profile | K8: Reported | L8: 2026-10-11 | M8: Brand-safety note: legal controversies; reported betting-platform ambassadorships (not listed). Handle not confirmed by tracker in this research.
A9: Elvish Yadav | B9: https://www.instagram.com/elvish_yadav/ | C9: 21100000 | D9: Estimate (~21.1M) | E9: Qoruz (Aug 2026) | F9: https://qoruz.com/theindianviner/instagram | G9: 2026-08 | H9: Elo Elo | I9: https://blog.jumpp.finance/financial-management/net-worth/elvish-yadav-net-wort/ | J9: Finance blog profile | K9: Reported | L9: 2026-10-11
A10: Ashish Chanchlani | B10: https://www.instagram.com/ashishchanchlani/ | C10: 17700000 | D10: Estimate (17.4-17.8M) | E10: HypeAuditor / Qoruz (Aug 2026) | F10: https://hypeauditor.com/instagram/ashishchanchlani/ | G10: 2026-08 | H10: The Souled Store | I10: https://in.fashionnetwork.com/news/The-Souled-Store-collaborates-with-Ashish-Chanchlani-for-new-collection,1361023.html | J10: Fashion trade media (Dec 2021) - apparel collection | K10: Confirmed | L10: 2026-10-11
A11: Garima Chaurasia (Gima Ashi) | B11: https://www.instagram.com/gima_ashi/ | C11: 14600000 | D11: Estimate (~13.9-14.6M) | E11: Socialveins | F11: https://socialveins.com/influencer/instagram/gima_ashi | G11: 2026 | H11: No specific brand collaboration verified (runs @thriftiquebygima store) | I11: https://socialveins.com/influencer/instagram/gima_ashi | J11: Directory profile | K11: Unverified | L11: 2026-10-11
A12: Lilly Singh | B12: https://www.instagram.com/lilly/ | C12: 13200000 | D12: Estimate (13.2-13.5M) | E12: Qoruz | F12: https://qoruz.com/lilly/instagram | G12: 2026 | H12: Ardene | I12: https://us.fashionnetwork.com/news/Canadian-retailer-ardene-collaborates-with-lilly-singh,1131537.html | J12: Fashion trade media - capsule collection (Aug 2019) | K12: Confirmed | L12: 2026-10-11 | M12: Indian-origin creator based in North America.
A13: Abhishek Malhan (Fukra Insaan) | B13: https://www.instagram.com/fukra_insaan/ | C13: 12500000 | D13: Estimate (~12.5M) | E13: Qoruz / Socialveins | F13: https://socialveins.com/influencer/instagram/fukra_insaan | G13: 2026 | H13: No specific brand collaboration verified | I13: https://www.favikon.com/blog/top-instagram-influencers-india | J13: Ranking site | K13: Unverified | L13: 2026-10-11
A14: Adnaan Shaikh | B14: https://www.instagram.com/adnaan_07dz/ | C14: 11600000 | D14: Estimate (11.5-11.9M) | E14: Qoruz / HypeAuditor | F14: https://hypeauditor.com/instagram/adnaan_07dz/ | G14: 2026 | H14: No named brand verified (fashion-brand campaign described) | I14: https://qoruz.com/adnaan/instagram | J14: Directory profile | K14: Unverified | L14: 2026-10-11
A15: Sourav Joshi | B15: https://www.instagram.com/souravjoshivlogs/ | C15: 10900000 | D15: Estimate (~10.9M) | E15: HypeAuditor (Jul 2026) / Qoruz | F15: https://hypeauditor.com/instagram/souravjoshivlogs/ | G15: 2026-07-25 | H15: Lava | I15: https://www.mediainfoline.com/advertising/lava-partners-with-youtube-star-sourav-joshi | J15: Brand partnership announcement (Aug 2024) | K15: Confirmed | L15: 2026-10-11
A16: Ashnoor Kaur | B16: https://www.instagram.com/ashnoorkaur/ | C16: 10400000 | D16: Estimate (~10.4M) | E16: Qoruz / HypeAuditor (Jul 2026) | F16: https://hypeauditor.com/instagram/ashnoorkaur/ | G16: 2026-07 | H16: Tic Tac | I16: https://creatordb.app/creatorstats/ashnoorkaur/ | J16: Analytics platform brand-partnership log | K16: Reported | L16: 2026-10-11 | M16: Former TV actor; review against your celebrity-exclusion policy.
A17: Vishal Pandey | B17: https://www.instagram.com/vishalpandey_21/ | C17: 9300000 | D17: Estimate (~9.3M) | E17: Qoruz | F17: https://qoruz.com/vishalpandey_21/instagram | G17: 2026 | H17: Farq Clothing (own label) | I17: https://qoruz.com/vishalpandey_21/instagram | J17: Creator bio via analytics profile | K17: Reported | L17: 2026-10-11
A18: Faiz Baloch | B18: https://www.instagram.com/faizbaloch_07/ | C18: 9000000 | D18: Estimate (~9M) | E18: Qoruz | F18: https://qoruz.com/faizbaloch_07/instagram | G18: 2026 | H18: No specific brand collaboration verified | I18: https://qoruz.com/faizbaloch_07/instagram | J18: Directory profile | K18: Unverified | L18: 2026-10-11
A19: Prajakta Koli | B19: https://www.instagram.com/mostlysane/ | C19: 8700000 | D19: Estimate (~8.7M) | E19: Qoruz | F19: https://qoruz.com/iamMostlySane/instagram | G19: 2026 | H19: Go Colors (MostlySane Collection) | I19: https://www.impactonnet.com/more-from-impact/go-colors-launches-mostlysane-collection-campaign-with-prajakta-koli-14727.html | J19: Campaign announcement (Jun 2026) | K19: Confirmed | L19: 2026-10-11
A20: Prajakta Koli | B20: https://www.instagram.com/mostlysane/ | C20: 8700000 | D20: Estimate (~8.7M) | E20: Qoruz | F20: https://qoruz.com/iamMostlySane/instagram | G20: 2026 | H20: YouTube; Google; WhatsApp | I20: https://www.azafashions.com/coverstory/prajakta-koli | J20: Fashion retailer cover story | K20: Reported | L20: 2026-10-11
A21: Nagma Mirajkar | B21: https://www.instagram.com/nagmamirajkar/ | C21: 8200000 | D21: Estimate (8.0-8.3M) | E21: Qoruz / Socialveins | F21: https://socialveins.com/influencer/instagram/nagmamirajkar | G21: 2026 | H21: Estée Lauder; Netflix; Fashion Nova | I21: https://india.entrepreneur.com/en-in/social-media/nagma-mirajkar-changing-the-face-of-fashion-digitally/442782 | J21: Business media profile | K21: Confirmed | L21: 2026-10-11
A22: Nagma Mirajkar | B22: https://www.instagram.com/nagmamirajkar/ | C22: 8200000 | D22: Estimate (8.0-8.3M) | E22: Qoruz / Socialveins | F22: https://socialveins.com/influencer/instagram/nagmamirajkar | G22: 2026 | H22: Maybelline New York; Aqualogica | I22: https://creatordb.app/creatorstats/nagmamirajkar/ | J22: Analytics platform brand-partnership log | K22: Reported | L22: 2026-10-11
A23: Nagma Mirajkar | B23: https://www.instagram.com/nagmamirajkar/ | C23: 8200000 | D23: Estimate (8.0-8.3M) | E23: Qoruz / Socialveins | F23: https://socialveins.com/influencer/instagram/nagmamirajkar | G23: 2026 | H23: H&M; Myntra; Urbanic; Reliance Trends; Amazon Fashion | I23: https://idiotic.media/top-macro-influencers-on-instagram-to-partner-with-in-2025/ | J23: Agency listicle | K23: Reported | L23: 2026-10-11
A24: Rits Badiani | B24: https://www.instagram.com/rits_badiani/ | C24: 7600000 | D24: Estimate (~7.6M) | E24: Qoruz (Aug 2026) | F24: https://qoruz.com/rits_badiani/instagram | G24: 2026-08 | H24: Savana | I24: https://app.favikon.com/public/profile/rits-badiani-6422c87642f73f49a4a7e651/ | J24: Ranking site profile | K24: Reported | L24: 2026-10-11
A25: Aditi Bhatia | B25: https://www.instagram.com/aditi_bhatia4/ | C25: 7500000 | D25: Estimate (~7.5M) | E25: Qoruz | F25: https://qoruz.com/aditi_bhatia4_1/instagram | G25: 2026 | H25: No named brand verified (beauty/fashion/travel work described) | I25: https://www.thehandbook.com/influencer/aditi-bhatia-🎭/ | J25: Directory profile | K25: Unverified | L25: 2026-10-11 | M25: Former TV actor; review against your celebrity-exclusion policy.
A26: Sakshi Malik | B26: https://www.instagram.com/sakshimalikk/ | C26: 7200000 | D26: Estimate (~7.2M) | E26: Qoruz (Aug 2026) | F26: https://qoruz.com/sakshimalik211/instagram | G26: 2026-08 | H26: PC Jewellers; Freshlook; Nykaa | I26: https://www.thecityceleb.com/biography/celebrity/actress/sakshi-malik-biography-awards-age-religion-movies-husband-height-ethnicity-net-worth/ | J26: Biography site (TV commercials) | K26: Reported | L26: 2026-10-11 | M26: Model/actress known from 'Bom Diggy Diggy' - not the Olympic wrestler of the same name.
A27: RJ Karishma | B27: https://www.instagram.com/rjkarishma/ | C27: 6900000 | D27: Estimate (6.9-7.0M) | E27: Qoruz / Socialveins | F27: https://qoruz.com/rjkarishma/instagram | G27: 2026 | H27: Myntra | I27: https://www.onmanorama.com/lifestyle/beauty-and-fashion/2022/11/30/myntra-host-its-first-ever-creator-fest-on-dec-2.html ; https://www.indiaretailing.com/?p=152683 | J27: Media reports naming creators Myntra has engaged (2022) | K27: Reported | L27: 2026-10-11
A28: Parul Garg | B28: https://www.instagram.com/parulgargmakeup/ | C28: 6800000 | D28: Estimate (~6.8M) | E28: Qoruz / Socialveins | F28: https://qoruz.com/parulgargmakeup/instagram | G28: 2026 | H28: Parul Garg Beauty (own brand) | I28: https://creatordb.app/creatorstats/parulgargmakeup/ | J28: Analytics profile | K28: Reported | L28: 2026-10-11
A29: Shadan Farooqui | B29: https://www.instagram.com/shadanfarooqui/ | C29: 6400000 | D29: Estimate (6.4-6.8M) | E29: Qoruz (Aug 2026) | F29: https://qoruz.com/saddu07dz/instagram | G29: 2026-08 | H29: No named brand verified (beauty & fashion campaigns described) | I29: https://www.thehandbook.com/influencer/shadanfarooqui/ | J29: Directory profile | K29: Unverified | L29: 2026-10-11
A30: Mrunal Panchal | B30: https://www.instagram.com/mrunu/ | C30: 6100000 | D30: Estimate (5.6-6.2M) | E30: HypeAuditor / Qoruz | F30: https://hypeauditor.com/instagram/mrunu/ | G30: 2026-08 | H30: Maybelline New York; Sony LIV; Nivea | I30: https://india.entrepreneur.com/en-in/lifestyle/the-beauty-influencer-mrunal-panchal/442578 | J30: Business media profile (2023) | K30: Confirmed | L30: 2026-10-11
A31: Ranveer Allahbadia | B31: https://www.instagram.com/beerbiceps/ | C31: 5800000 | D31: Estimate (4.4-5.8M; sources differ) | E31: Qoruz (Jul 2026) | F31: https://qoruz.com/ranveerallahbadia_1/instagram | G31: 2026-07 | H31: AJIO; Samsung; Wow Skin Science; Spotify; Amazon Prime Video; Intel; boAt | I31: https://www.exchange4media.com/influence-zone-news/months-after-controversy-ranveer-allahbadia-returns-to-brand-collaborations-with-boat-147642.html | J31: Trade media report (Sep 2025) | K31: Confirmed | L31: 2026-10-11 | M31: Brand activity slowed after Feb 2025 controversy; boAt (Sep 2025) was first major deal afterwards.
A32: Aashika Bhatia | B32: https://www.instagram.com/_aashikabhatia_/ | C32: 5782248 | D32: Exact (tracker) | E32: CreatorDB | F32: https://creatordb.app/creatorstats/_aashikabhatia_/ | G32: 2026-08-05 | H32: No specific brand collaboration verified | I32: https://creatordb.app/creatorstats/_aashikabhatia_/ | J32: Analytics profile | K32: Unverified | L32: 2026-10-11
A33: Pearle Maaney | B33: https://www.instagram.com/pearlemaany/ | C33: 5300000 | D33: Estimate (~5.3M) | E33: CreatorDB (Sep 2026) / Qoruz | F33: https://creatordb.app/creatorstats/pearlemaany/ | G33: 2026-09-26 | H33: Google India (Onam campaign) | I33: https://www.exchange4media.com/influence-zone-news/from-pearle-maaney-to-ahaana-krishna-who-are-south-indias-top-10-influencers-139373.html | J33: Trade media ranking | K33: Reported | L33: 2026-10-11
A34: Roshni Kapoor | B34: https://www.instagram.com/roshni.kapoor/ | C34: 5100000 | D34: Estimate (~5.1M) | E34: Qoruz | F34: https://qoruz.com/flattummytea_com/instagram | G34: 2026 | H34: No specific brand collaboration verified | I34: https://qoruz.com/flattummytea_com/instagram | J34: Directory profile | K34: Unverified | L34: 2026-10-11
A35: Dimpi Sanghvi | B35: https://www.instagram.com/dimpisanghvi_ws/ | C35: 4993000 | D35: Estimate (~5.0M) | E35: DolphinRadar / Qoruz (Aug 2026) | F35: https://www.dolphinradar.com/starInfo/dimpisanghvi_ws | G35: 2026-08 | H35: Brand partnerships described; no brand named | I35: https://www.dolphinradar.com/starInfo/dimpisanghvi_ws | J35: Analytics profile | K35: Unverified | L35: 2026-10-11
A36: Apoorva Mukhija (The Rebel Kid) | B36: https://www.instagram.com/the.rebel.kid/ | C36: 4600000 | D36: Estimate (4.4-4.6M) | E36: Qoruz / Storyboard18 (Mar 2026) | F36: https://www.storyboard18.com/trending/inside-collective-artists-networks-creator-roster-awez-darbar-bhuvan-bam-among-top-influencers-91374.htm | G36: 2026-03 | H36: Freakins | I36: https://afaqs.com/news/influencer-marketing/denim-brand-freakins-collaborates-with-apoorva-makhija-a-genz-influencer | J36: Trade media - co-branded denim collection | K36: Confirmed | L36: 2026-10-11 | M36: Brand-safety note: 2025 'India's Got Latent' controversy; removed as IIFA ambassador.
A37: Apoorva Mukhija (The Rebel Kid) | B37: https://www.instagram.com/the.rebel.kid/ | C37: 4600000 | D37: Estimate (4.4-4.6M) | E37: Qoruz / Storyboard18 (Mar 2026) | F37: https://www.storyboard18.com/trending/inside-collective-artists-networks-creator-roster-awez-darbar-bhuvan-bam-among-top-influencers-91374.htm | G37: 2026-03 | H37: L'Oréal Paris; MARS Cosmetics; Aqualogica; Flipkart; Airtel; Swiggy Instamart | I37: https://motionapp.com/creator/therebelkid/ | J37: Ad-tracking platform brand list | K37: Reported | L37: 2026-10-11
A38: Ansh Pandit | B38: https://www.instagram.com/ianshpandit/ | C38: 4500000 | D38: Estimate (4.5-4.9M) | E38: Qoruz (Aug 2026) | F38: https://qoruz.com/ianshpandit/instagram | G38: 2026-08 | H38: No specific brand collaboration verified | I38: https://qoruz.com/ianshpandit/instagram | J38: Directory profile | K38: Unverified | L38: 2026-10-11
A39: Aarush Bhola | B39: https://www.instagram.com/aarushbhola17/ | C39: 4430000 | D39: Estimate (4.2-4.5M) | E39: CreatorDB | F39: https://creatordb.app/creatorstats/aarushbhola17/ | G39: 2026-07-30 | H39: BigMuscles Nutrition; Pintola | I39: https://creatordb.app/creatorstats/aarushbhola17/ | J39: Analytics platform brand-partnership log | K39: Reported | L39: 2026-10-11
A40: Kusha Kapila | B40: https://www.instagram.com/kushakapila/ | C40: 4400000 | D40: Estimate (~4.4M) | E40: Qoruz (Aug 2026) | F40: https://qoruz.com/kushakapila/instagram | G40: 2026-08 | H40: Nykaa; Myntra; Bata; Swiggy Instamart; Tira Beauty; Underneat | I40: https://motionapp.com/creator/kusha-kapila/ | J40: Ad-tracking platform brand list | K40: Reported | L40: 2026-10-11
...

Sheet Category Summary
A1: Primary Category | B1: Number of Creators | C1: Share of Total
A2: Fashion | B2: =COUNTIF('Influencer Database'!$D$2:$D$80,A2) -> 4 | C2: =IF($B$14=0,0,B2/$B$14) -> 0.050632911
A3: Men's Fashion | B3: =COUNTIF('Influencer Database'!$D$2:$D$80,A3) -> 5 | C3: =IF($B$14=0,0,B3/$B$14) -> 0.063291139
A4: Women's Fashion | B4: =COUNTIF('Influencer Database'!$D$2:$D$80,A4) -> 4 | C4: =IF($B$14=0,0,B4/$B$14) -> 0.050632911
A5: Lifestyle | B5: =COUNTIF('Influencer Database'!$D$2:$D$80,A5) -> 7 | C5: =IF($B$14=0,0,B5/$B$14) -> 0.088607595
A6: Fashion & Lifestyle | B6: =COUNTIF('Influencer Database'!$D$2:$D$80,A6) -> 16 | C6: =IF($B$14=0,0,B6/$B$14) -> 0.20253165
A7: Streetwear | B7: =COUNTIF('Influencer Database'!$D$2:$D$80,A7) -> 0 | C7: =IF($B$14=0,0,B7/$B$14) -> 0
A8: Luxury Fashion | B8: =COUNTIF('Influencer Database'!$D$2:$D$80,A8) -> 3 | C8: =IF($B$14=0,0,B8/$B$14) -> 0.037974684
A9: Beauty & Fashion | B9: =COUNTIF('Influencer Database'!$D$2:$D$80,A9) -> 10 | C9: =IF($B$14=0,0,B9/$B$14) -> 0.12658228
A10: Fashion Modelling | B10: =COUNTIF('Influencer Database'!$D$2:$D$80,A10) -> 2 | C10: =IF($B$14=0,0,B10/$B$14) -> 0.025316456
A11: Lifestyle Vlogging | B11: =COUNTIF('Influencer Database'!$D$2:$D$80,A11) -> 3 | C11: =IF($B$14=0,0,B11/$B$14) -> 0.037974684
A12: Travel & Lifestyle | B12: =COUNTIF('Influencer Database'!$D$2:$D$80,A12) -> 6 | C12: =IF($B$14=0,0,B12/$B$14) -> 0.075949367
A13: Fashion Entertainment | B13: =COUNTIF('Influencer Database'!$D$2:$D$80,A13) -> 19 | C13: =IF($B$14=0,0,B13/$B$14) -> 0.24050633
A14: Total | B14: =SUM(B2:B13) -> 79 | C14: =SUM(C2:C13) -> 1
A15: Check: rows in Influencer Database | B15: =COUNTA('Influencer Database'!$A$2:$A$80) -> 79
A17: Creators with ≥1 Confirmed/Reported brand | B17: =COUNTIF('Influencer Database'!$F$2:$F$80,"<>Not verified") -> 50
A18: Combined followers (all creators) | B18: =SUM('Influencer Database'!$C$2:$C$80) -> 507918222
A20: Note: Streetwear has no qualifying creator in this edition; no 1M+ Indian streetwear-first creator could be verified.

Sheet Excluded Candidates
A1: Candidate | B1: Reason for Exclusion
A2: Juhi Godambe | B2: Below 1M (~584K, CreatorDB Oct 2026)
A3: Sejal Kumar | B3: Below 1M (~785K, Qoruz Jul 2026)
A4: Santoshi Shetty | B4: Below 1M (~678K, CreatorDB Oct 2026)
A5: Debasree Banerjee | B5: Below 1M on Instagram (~298K)
A6: Malvika Sitlani | B6: Below 1M (~700K)
A7: Larissa D'Sa | B7: Below 1M (~793K)
A8: Sakshi Sindwani | B8: Below 1M (~711K)
A9: Shereen Sikka (Love and Other Bugs) | B9: Below 1M (~342K)
A10: Shruti Arjun Anand | B10: Below 1M on Instagram (~466K); account reported inactive
A11: Malini Agarwal | B11: Personal account ~249K; @missmalini is a company account sold in 2025
A12: Riya Jain | B12: Below 1M (~411K)
... A58: Virat Kohli, Deepika Padukone, Alia Bhatt, etc. | B58: A-list celebrities - excluded by brief

Sheet Methodology
A1: Item | B1: Detail
A2: Research date | B2: 2026-10-11
A3: Scope | B3: Indian (or Indian-origin) Instagram creators with 1,000,000+ followers whose primary or secondary content is fashion and/or lifestyle. A-list film stars and athletes excluded.
A4: Result | B4: 79 qualifying creators. The 100-150 target was NOT reached: every additional candidate checked either fell below 1M, showed signs of follower inflation, or had no verifiable fashion/lifestyle link. Per the brief, the list was not padded.
A5: Follower counts | B5: Live Instagram profiles could not be accessed from the research environment, so counts come from third-party trackers (CreatorDB, Qoruz, HypeAuditor, DolphinRadar, Socialveins) and media reports dated Mar 2025 - Oct 2026. 'Exact (tracker)' = exact figure published by a tracker; 'Estimate' = rounded tracker figure (e.g. 4.4M recorded as 4,400,000). Verify live before contracting.
A6: Borderline accounts | B6: Aashna Shroff, Aashna Hegde, Kirti Mehra and Aisha Mahdi sit at ~1.0-1.16M in at least one tracker; re-check before use.
A7: Brand evidence strength | B7: Confirmed = trade/business media report, brand announcement, or creator interview naming the brand. Reported = analytics-platform partnership log, agency listicle or biography site. Unverified = no named brand found; shown as 'Not verified' in the main table. Gifted products, tags and affiliate codes were not counted where distinguishable.
A8: Brand-safety flags | B8: See Notes column in 'Sources & Verification' (e.g. Ranveer Allahbadia, Apoorva Mukhija, Elvish Yadav, Diya Krishna).
A9: Celebrity boundary | B9: Former TV/child actors who are now primarily Instagram creators (Jannat Zubair, Avneet Kaur, Anushka Sen, Ashnoor Kaur, Aditi Bhatia) are included but flagged - remove if your policy treats them as mainstream celebrities.
A10: Instagram IDs | B10: Handles were taken from tracker profiles. Uorfi Javed (@urf7i), Elvish Yadav (@elvish_yadav), Orry (@orry1) and Sneha Arora (@snehaarora197) were not confirmed by a tracker page in this research - verify.
